[2022-02-02 10:56:20,420] {taskinstance.py:903} INFO - Dependencies all met for <TaskInstance: twitter_dag.twitter_aluraonline 2022-02-02T13:39:55.617217+00:00 [queued]>
[2022-02-02 10:56:20,433] {taskinstance.py:903} INFO - Dependencies all met for <TaskInstance: twitter_dag.twitter_aluraonline 2022-02-02T13:39:55.617217+00:00 [queued]>
[2022-02-02 10:56:20,434] {taskinstance.py:1095} INFO - 
--------------------------------------------------------------------------------
[2022-02-02 10:56:20,434] {taskinstance.py:1096} INFO - Starting attempt 1 of 1
[2022-02-02 10:56:20,434] {taskinstance.py:1097} INFO - 
--------------------------------------------------------------------------------
[2022-02-02 10:56:20,448] {taskinstance.py:1115} INFO - Executing <Task(TwitterOperator): twitter_aluraonline> on 2022-02-02T13:39:55.617217+00:00
[2022-02-02 10:56:20,452] {standard_task_runner.py:52} INFO - Started process 19727 to run task
[2022-02-02 10:56:20,463] {standard_task_runner.py:76} INFO - Running: ['airflow', 'tasks', 'run', 'twitter_dag', 'twitter_aluraonline', '2022-02-02T13:39:55.617217+00:00', '--job-id', '9', '--pool', 'default_pool', '--raw', '--subdir', 'DAGS_FOLDER/twitter_dag.py', '--cfg-path', '/var/folders/k6/528t8tnx5llf4w8y5xx1rrm80000gn/T/tmpbk0exx86', '--error-file', '/var/folders/k6/528t8tnx5llf4w8y5xx1rrm80000gn/T/tmpry5zoxnr']
[2022-02-02 10:56:20,465] {standard_task_runner.py:77} INFO - Job 9: Subtask twitter_aluraonline
[2022-02-02 10:56:20,511] {logging_mixin.py:109} INFO - Running <TaskInstance: twitter_dag.twitter_aluraonline 2022-02-02T13:39:55.617217+00:00 [running]> on host 1.0.0.127.in-addr.arpa
[2022-02-02 10:56:20,568] {taskinstance.py:1254} INFO - Exporting the following env vars:
AIRFLOW_CTX_DAG_OWNER=airflow
AIRFLOW_CTX_DAG_ID=twitter_dag
AIRFLOW_CTX_TASK_ID=twitter_aluraonline
AIRFLOW_CTX_EXECUTION_DATE=2022-02-02T13:39:55.617217+00:00
AIRFLOW_CTX_DAG_RUN_ID=manual__2022-02-02T13:39:55.617217+00:00
[2022-02-02 10:56:20,587] {taskinstance.py:1463} ERROR - Task failed with exception
Traceback (most recent call last):
  File "/Users/bezerraescossia/Github/studies/twitter-project/.venv/lib/python3.7/site-packages/airflow/models/taskinstance.py", line 1165, in _run_raw_task
    self._prepare_and_execute_task_with_callbacks(context, task)
  File "/Users/bezerraescossia/Github/studies/twitter-project/.venv/lib/python3.7/site-packages/airflow/models/taskinstance.py", line 1283, in _prepare_and_execute_task_with_callbacks
    result = self._execute_task(context, task_copy)
  File "/Users/bezerraescossia/Github/studies/twitter-project/.venv/lib/python3.7/site-packages/airflow/models/taskinstance.py", line 1313, in _execute_task
    result = task_copy.execute(context=context)
  File "/Users/bezerraescossia/Github/studies/twitter-project/airflow/plugins/operators/twitter_operator.py", line 49, in execute
    for pg in hook.run():
  File "/Users/bezerraescossia/Github/studies/twitter-project/airflow/plugins/hooks/twitter_hook.py", line 52, in run
    session = self.get_conn()
  File "/Users/bezerraescossia/Github/studies/twitter-project/.venv/lib/python3.7/site-packages/airflow/providers/http/hooks/http.py", line 72, in get_conn
    conn = self.get_connection(self.http_conn_id)
  File "/Users/bezerraescossia/Github/studies/twitter-project/.venv/lib/python3.7/site-packages/airflow/hooks/base.py", line 68, in get_connection
    conn = Connection.get_connection_from_secrets(conn_id)
  File "/Users/bezerraescossia/Github/studies/twitter-project/.venv/lib/python3.7/site-packages/airflow/models/connection.py", line 379, in get_connection_from_secrets
    raise AirflowNotFoundException(f"The conn_id `{conn_id}` isn't defined")
airflow.exceptions.AirflowNotFoundException: The conn_id `twitter_default` isn't defined
[2022-02-02 10:56:20,591] {taskinstance.py:1513} INFO - Marking task as FAILED. dag_id=twitter_dag, task_id=twitter_aluraonline, execution_date=20220202T133955, start_date=20220202T135620, end_date=20220202T135620
[2022-02-02 10:56:20,649] {local_task_job.py:151} INFO - Task exited with return code 1
[2022-02-02 10:56:20,685] {local_task_job.py:261} INFO - 0 downstream tasks scheduled from follow-on schedule check
